2019-02-18 11:55:13,296 INFO org.apache.hadoop.yarn.server.resourcemanager.ResourceManager: STARTUP_MSG: 
/************************************************************
STARTUP_MSG: Starting ResourceManager
STARTUP_MSG:   user = hdpuser
STARTUP_MSG:   host = ubuntu/127.0.1.1
STARTUP_MSG:   args = []
STARTUP_MSG:   version = 2.8.1
STARTUP_MSG:   build = https://git-wip-us.apache.org/repos/asf/hadoop.git -r 20fe5304904fc2f5a18053c389e43cd26f7a70fe; compiled by 'vinodkv' on 2017-06-02T06:14Z
STARTUP_MSG:   java = 1.8.0_201
************************************************************/
2019-02-18 11:55:13,345 INFO org.apache.hadoop.yarn.server.resourcemanager.ResourceManager: registered UNIX signal handlers for [TERM, HUP, INT]
2019-02-18 11:55:15,790 INFO org.apache.hadoop.conf.Configuration: found resource core-site.xml at file:/usr/local/hadoop-2.8.1/etc/hadoop/core-site.xml
2019-02-18 11:55:16,282 INFO org.apache.hadoop.security.Groups: clearing userToGroupsMap cache
2019-02-18 11:55:16,702 INFO org.apache.hadoop.conf.Configuration: found resource yarn-site.xml at file:/usr/local/hadoop-2.8.1/etc/hadoop/yarn-site.xml
2019-02-18 11:55:18,065 INFO org.apache.hadoop.yarn.event.AsyncDispatcher: Registering class org.apache.hadoop.yarn.server.resourcemanager.RMFatalEventType for class org.apache.hadoop.yarn.server.resourcemanager.ResourceManager$RMFatalEventDispatcher
2019-02-18 11:55:19,650 INFO org.apache.hadoop.yarn.server.resourcemanager.security.NMTokenSecretManagerInRM: NMTokenKeyRollingInterval: 86400000ms and NMTokenKeyActivationDelay: 900000ms
2019-02-18 11:55:19,684 INFO org.apache.hadoop.yarn.server.resourcemanager.security.RMContainerTokenSecretManager: ContainerTokenKeyRollingInterval: 86400000ms and ContainerTokenKeyActivationDelay: 900000ms
2019-02-18 11:55:19,714 INFO org.apache.hadoop.yarn.server.resourcemanager.security.AMRMTokenSecretManager: AMRMTokenKeyRollingInterval: 86400000ms and AMRMTokenKeyActivationDelay: 900000 ms
2019-02-18 11:55:20,001 INFO org.apache.hadoop.yarn.event.AsyncDispatcher: Registering class org.apache.hadoop.yarn.server.resourcemanager.recovery.RMStateStoreEventType for class org.apache.hadoop.yarn.server.resourcemanager.recovery.RMStateStore$ForwardingEventHandler
2019-02-18 11:55:20,017 INFO org.apache.hadoop.yarn.event.AsyncDispatcher: Registering class org.apache.hadoop.yarn.server.resourcemanager.NodesListManagerEventType for class org.apache.hadoop.yarn.server.resourcemanager.NodesListManager
2019-02-18 11:55:20,018 INFO org.apache.hadoop.yarn.server.resourcemanager.ResourceManager: Using Scheduler: org.apache.hadoop.yarn.server.resourcemanager.scheduler.capacity.CapacityScheduler
2019-02-18 11:55:20,163 INFO org.apache.hadoop.yarn.event.AsyncDispatcher: Registering class org.apache.hadoop.yarn.server.resourcemanager.scheduler.event.SchedulerEventType for class org.apache.hadoop.yarn.server.resourcemanager.ResourceManager$SchedulerEventDispatcher
2019-02-18 11:55:20,181 INFO org.apache.hadoop.yarn.event.AsyncDispatcher: Registering class org.apache.hadoop.yarn.server.resourcemanager.rmapp.RMAppEventType for class org.apache.hadoop.yarn.server.resourcemanager.ResourceManager$ApplicationEventDispatcher
2019-02-18 11:55:20,186 INFO org.apache.hadoop.yarn.event.AsyncDispatcher: Registering class org.apache.hadoop.yarn.server.resourcemanager.rmapp.attempt.RMAppAttemptEventType for class org.apache.hadoop.yarn.server.resourcemanager.ResourceManager$ApplicationAttemptEventDispatcher
2019-02-18 11:55:20,187 INFO org.apache.hadoop.yarn.event.AsyncDispatcher: Registering class org.apache.hadoop.yarn.server.resourcemanager.rmnode.RMNodeEventType for class org.apache.hadoop.yarn.server.resourcemanager.ResourceManager$NodeEventDispatcher
2019-02-18 11:55:20,409 INFO org.apache.hadoop.metrics2.impl.MetricsConfig: loaded properties from hadoop-metrics2.properties
2019-02-18 11:55:20,767 INFO org.apache.hadoop.metrics2.impl.MetricsSystemImpl: Scheduled Metric snapshot period at 10 second(s).
2019-02-18 11:55:20,769 INFO org.apache.hadoop.metrics2.impl.MetricsSystemImpl: ResourceManager metrics system started
2019-02-18 11:55:20,856 INFO org.apache.hadoop.yarn.event.AsyncDispatcher: Registering class org.apache.hadoop.yarn.server.resourcemanager.RMAppManagerEventType for class org.apache.hadoop.yarn.server.resourcemanager.RMAppManager
2019-02-18 11:55:20,911 INFO org.apache.hadoop.yarn.event.AsyncDispatcher: Registering class org.apache.hadoop.yarn.server.resourcemanager.amlauncher.AMLauncherEventType for class org.apache.hadoop.yarn.server.resourcemanager.amlauncher.ApplicationMasterLauncher
2019-02-18 11:55:20,923 INFO org.apache.hadoop.yarn.server.resourcemanager.RMNMInfo: Registered RMNMInfo MBean
2019-02-18 11:55:20,966 INFO org.apache.hadoop.yarn.security.YarnAuthorizationProvider: org.apache.hadoop.yarn.security.ConfiguredYarnAuthorizer is instiantiated.
2019-02-18 11:55:20,980 INFO org.apache.hadoop.util.HostsFileReader: Refreshing hosts (include/exclude) list
2019-02-18 11:55:21,023 INFO org.apache.hadoop.conf.Configuration: found resource capacity-scheduler.xml at file:/usr/local/hadoop-2.8.1/etc/hadoop/capacity-scheduler.xml
2019-02-18 11:55:21,386 INFO org.apache.hadoop.yarn.server.resourcemanager.scheduler.capacity.CapacitySchedulerConfiguration: max alloc mb per queue for root is undefined
2019-02-18 11:55:21,386 INFO org.apache.hadoop.yarn.server.resourcemanager.scheduler.capacity.CapacitySchedulerConfiguration: max alloc vcore per queue for root is undefined
2019-02-18 11:55:21,435 INFO org.apache.hadoop.yarn.server.resourcemanager.scheduler.capacity.ParentQueue: root, capacity=1.0, asboluteCapacity=1.0, maxCapacity=1.0, asboluteMaxCapacity=1.0, state=RUNNING, acls=ADMINISTER_QUEUE:*SUBMIT_APP:*, labels=*,, offswitchPerHeartbeatLimit = 1, reservationsContinueLooking=true
2019-02-18 11:55:21,435 INFO org.apache.hadoop.yarn.server.resourcemanager.scheduler.capacity.ParentQueue: Initialized parent-queue root name=root, fullname=root
2019-02-18 11:55:21,489 INFO org.apache.hadoop.yarn.server.resourcemanager.scheduler.capacity.CapacitySchedulerConfiguration: max alloc mb per queue for root.default is undefined
2019-02-18 11:55:21,489 INFO org.apache.hadoop.yarn.server.resourcemanager.scheduler.capacity.CapacitySchedulerConfiguration: max alloc vcore per queue for root.default is undefined
2019-02-18 11:55:21,509 INFO org.apache.hadoop.yarn.server.resourcemanager.scheduler.capacity.LeafQueue: Initializing default
capacity = 1.0 [= (float) configuredCapacity / 100 ]
asboluteCapacity = 1.0 [= parentAbsoluteCapacity * capacity ]
maxCapacity = 1.0 [= configuredMaxCapacity ]
absoluteMaxCapacity = 1.0 [= 1.0 maximumCapacity undefined, (parentAbsoluteMaxCapacity * maximumCapacity) / 100 otherwise ]
userLimit = 100 [= configuredUserLimit ]
userLimitFactor = 1.0 [= configuredUserLimitFactor ]
maxApplications = 10000 [= configuredMaximumSystemApplicationsPerQueue or (int)(configuredMaximumSystemApplications * absoluteCapacity)]
maxApplicationsPerUser = 10000 [= (int)(maxApplications * (userLimit / 100.0f) * userLimitFactor) ]
usedCapacity = 0.0 [= usedResourcesMemory / (clusterResourceMemory * absoluteCapacity)]
absoluteUsedCapacity = 0.0 [= usedResourcesMemory / clusterResourceMemory]
maxAMResourcePerQueuePercent = 0.1 [= configuredMaximumAMResourcePercent ]
minimumAllocationFactor = 0.875 [= (float)(maximumAllocationMemory - minimumAllocationMemory) / maximumAllocationMemory ]
maximumAllocation = <memory:8192, vCores:4> [= configuredMaxAllocation ]
numContainers = 0 [= currentNumContainers ]
state = RUNNING [= configuredState ]
acls = ADMINISTER_QUEUE:*SUBMIT_APP:* [= configuredAcls ]
nodeLocalityDelay = 40
labels=*,
reservationsContinueLooking = true
preemptionDisabled = true
defaultAppPriorityPerQueue = 0
2019-02-18 11:55:21,509 INFO org.apache.hadoop.yarn.server.resourcemanager.scheduler.capacity.CapacityScheduler: Initialized queue: default: capacity=1.0, absoluteCapacity=1.0, usedResources=<memory:0, vCores:0>, usedCapacity=0.0, absoluteUsedCapacity=0.0, numApps=0, numContainers=0
2019-02-18 11:55:21,510 INFO org.apache.hadoop.yarn.server.resourcemanager.scheduler.capacity.CapacityScheduler: Initialized queue: root: numChildQueue= 1, capacity=1.0, absoluteCapacity=1.0, usedResources=<memory:0, vCores:0>usedCapacity=0.0, numApps=0, numContainers=0
2019-02-18 11:55:21,511 INFO org.apache.hadoop.yarn.server.resourcemanager.scheduler.capacity.CapacityScheduler: Initialized root queue root: numChildQueue= 1, capacity=1.0, absoluteCapacity=1.0, usedResources=<memory:0, vCores:0>usedCapacity=0.0, numApps=0, numContainers=0
2019-02-18 11:55:21,511 INFO org.apache.hadoop.yarn.server.resourcemanager.scheduler.capacity.CapacityScheduler: Initialized queue mappings, override: false
2019-02-18 11:55:21,524 INFO org.apache.hadoop.yarn.server.resourcemanager.scheduler.capacity.CapacityScheduler: Initialized CapacityScheduler with calculator=class org.apache.hadoop.yarn.util.resource.DefaultResourceCalculator, minimumAllocation=<<memory:1024, vCores:1>>, maximumAllocation=<<memory:8192, vCores:4>>, asynchronousScheduling=false, asyncScheduleInterval=5ms
2019-02-18 11:55:21,533 INFO org.apache.hadoop.conf.Configuration: dynamic-resources.xml not found
2019-02-18 11:55:21,620 INFO org.apache.hadoop.yarn.server.resourcemanager.metrics.SystemMetricsPublisher: YARN system metrics publishing service is not enabled
2019-02-18 11:55:21,620 INFO org.apache.hadoop.yarn.server.resourcemanager.ResourceManager: Transitioning to active state
2019-02-18 11:55:21,677 INFO org.apache.hadoop.util.JvmPauseMonitor: Starting JVM pause monitor
2019-02-18 11:55:21,779 INFO org.apache.hadoop.yarn.server.resourcemanager.recovery.RMStateStore: Updating AMRMToken
2019-02-18 11:55:21,780 INFO org.apache.hadoop.yarn.server.resourcemanager.security.RMContainerTokenSecretManager: Rolling master-key for container-tokens
2019-02-18 11:55:21,780 INFO org.apache.hadoop.yarn.server.resourcemanager.security.NMTokenSecretManagerInRM: Rolling master-key for nm-tokens
2019-02-18 11:55:21,781 INFO org.apache.hadoop.security.token.delegation.AbstractDelegationTokenSecretManager: Updating the current master key for generating delegation tokens
2019-02-18 11:55:21,795 INFO org.apache.hadoop.yarn.server.resourcemanager.security.RMDelegationTokenSecretManager: storing master key with keyID 1
2019-02-18 11:55:21,795 INFO org.apache.hadoop.yarn.server.resourcemanager.recovery.RMStateStore: Storing RMDTMasterKey.
2019-02-18 11:55:21,803 INFO org.apache.hadoop.security.token.delegation.AbstractDelegationTokenSecretManager: Starting expired delegation token remover thread, tokenRemoverScanInterval=60 min(s)
2019-02-18 11:55:21,808 INFO org.apache.hadoop.security.token.delegation.AbstractDelegationTokenSecretManager: Updating the current master key for generating delegation tokens
2019-02-18 11:55:21,828 INFO org.apache.hadoop.yarn.event.AsyncDispatcher: Registering class org.apache.hadoop.yarn.nodelabels.event.NodeLabelsStoreEventType for class org.apache.hadoop.yarn.nodelabels.CommonNodeLabelsManager$ForwardingEventHandler
2019-02-18 11:55:21,827 INFO org.apache.hadoop.yarn.server.resourcemanager.security.RMDelegationTokenSecretManager: storing master key with keyID 2
2019-02-18 11:55:21,838 INFO org.apache.hadoop.yarn.server.resourcemanager.recovery.RMStateStore: Storing RMDTMasterKey.
2019-02-18 11:55:21,953 INFO org.apache.hadoop.ipc.CallQueueManager: Using callQueue: class java.util.concurrent.LinkedBlockingQueue queueCapacity: 5000 scheduler: class org.apache.hadoop.ipc.DefaultRpcScheduler
2019-02-18 11:55:22,056 INFO org.apache.hadoop.ipc.Server: Starting Socket Reader #1 for port 8031
2019-02-18 11:55:22,807 INFO org.apache.hadoop.yarn.factories.impl.pb.RpcServerFactoryPBImpl: Adding protocol org.apache.hadoop.yarn.server.api.ResourceTrackerPB to the server
2019-02-18 11:55:22,809 INFO org.apache.hadoop.ipc.Server: IPC Server Responder: starting
2019-02-18 11:55:22,893 INFO org.apache.hadoop.ipc.Server: IPC Server listener on 8031: starting
2019-02-18 11:55:22,960 INFO org.apache.hadoop.ipc.CallQueueManager: Using callQueue: class java.util.concurrent.LinkedBlockingQueue queueCapacity: 5000 scheduler: class org.apache.hadoop.ipc.DefaultRpcScheduler
2019-02-18 11:55:23,037 INFO org.apache.hadoop.ipc.Server: Starting Socket Reader #1 for port 8030
2019-02-18 11:55:23,139 INFO org.apache.hadoop.yarn.factories.impl.pb.RpcServerFactoryPBImpl: Adding protocol org.apache.hadoop.yarn.api.ApplicationMasterProtocolPB to the server
2019-02-18 11:55:23,152 INFO org.apache.hadoop.ipc.Server: IPC Server Responder: starting
2019-02-18 11:55:23,154 INFO org.apache.hadoop.ipc.Server: IPC Server listener on 8030: starting
2019-02-18 11:55:23,930 INFO org.apache.hadoop.ipc.CallQueueManager: Using callQueue: class java.util.concurrent.LinkedBlockingQueue queueCapacity: 5000 scheduler: class org.apache.hadoop.ipc.DefaultRpcScheduler
2019-02-18 11:55:23,948 INFO org.apache.hadoop.ipc.Server: Starting Socket Reader #1 for port 8032
2019-02-18 11:55:23,970 INFO org.apache.hadoop.yarn.factories.impl.pb.RpcServerFactoryPBImpl: Adding protocol org.apache.hadoop.yarn.api.ApplicationClientProtocolPB to the server
2019-02-18 11:55:23,991 INFO org.apache.hadoop.ipc.Server: IPC Server Responder: starting
2019-02-18 11:55:24,128 INFO org.apache.hadoop.yarn.server.resourcemanager.ResourceManager: Transitioned to active state
2019-02-18 11:55:24,136 INFO org.apache.hadoop.ipc.Server: IPC Server listener on 8032: starting
2019-02-18 11:55:24,610 INFO org.mortbay.log: Logging to org.slf4j.impl.Log4jLoggerAdapter(org.mortbay.log) via org.mortbay.log.Slf4jLog
2019-02-18 11:55:24,649 INFO org.apache.hadoop.security.authentication.server.AuthenticationFilter: Unable to initialize FileSignerSecretProvider, falling back to use random secrets.
2019-02-18 11:55:24,681 INFO org.apache.hadoop.http.HttpRequestLog: Http request log for http.requests.resourcemanager is not defined
2019-02-18 11:55:24,718 INFO org.apache.hadoop.http.HttpServer2: Added global filter 'safety' (class=org.apache.hadoop.http.HttpServer2$QuotingInputFilter)
2019-02-18 11:55:24,738 INFO org.apache.hadoop.http.HttpServer2: Added filter RMAuthenticationFilter (class=org.apache.hadoop.yarn.server.security.http.RMAuthenticationFilter) to context cluster
2019-02-18 11:55:24,739 INFO org.apache.hadoop.http.HttpServer2: Added filter RMAuthenticationFilter (class=org.apache.hadoop.yarn.server.security.http.RMAuthenticationFilter) to context static
2019-02-18 11:55:24,752 INFO org.apache.hadoop.http.HttpServer2: Added filter RMAuthenticationFilter (class=org.apache.hadoop.yarn.server.security.http.RMAuthenticationFilter) to context logs
2019-02-18 11:55:24,753 INFO org.apache.hadoop.http.HttpServer2: Added filter static_user_filter (class=org.apache.hadoop.http.lib.StaticUserWebFilter$StaticUserFilter) to context cluster
2019-02-18 11:55:24,753 INFO org.apache.hadoop.http.HttpServer2: Added filter static_user_filter (class=org.apache.hadoop.http.lib.StaticUserWebFilter$StaticUserFilter) to context static
2019-02-18 11:55:24,759 INFO org.apache.hadoop.http.HttpServer2: Added filter static_user_filter (class=org.apache.hadoop.http.lib.StaticUserWebFilter$StaticUserFilter) to context logs
2019-02-18 11:55:24,788 INFO org.apache.hadoop.http.HttpServer2: adding path spec: /cluster/*
2019-02-18 11:55:24,788 INFO org.apache.hadoop.http.HttpServer2: adding path spec: /ws/*
2019-02-18 11:55:26,812 INFO org.apache.hadoop.yarn.webapp.WebApps: Registered webapp guice modules
2019-02-18 11:55:26,818 INFO org.apache.hadoop.http.HttpServer2: Jetty bound to port 8088
2019-02-18 11:55:26,818 INFO org.mortbay.log: jetty-6.1.26
2019-02-18 11:55:26,984 INFO org.mortbay.log: Extract jar:file:/usr/local/hadoop-2.8.1/share/hadoop/yarn/hadoop-yarn-common-2.8.1.jar!/webapps/cluster to /tmp/Jetty_0_0_0_0_8088_cluster____u0rgz3/webapp
2019-02-18 11:55:28,038 INFO org.apache.hadoop.security.token.delegation.AbstractDelegationTokenSecretManager: Updating the current master key for generating delegation tokens
2019-02-18 11:55:28,052 INFO org.apache.hadoop.security.token.delegation.AbstractDelegationTokenSecretManager: Starting expired delegation token remover thread, tokenRemoverScanInterval=60 min(s)
2019-02-18 11:55:28,053 INFO org.apache.hadoop.security.token.delegation.AbstractDelegationTokenSecretManager: Updating the current master key for generating delegation tokens
2019-02-18 11:55:35,169 INFO org.mortbay.log: Started HttpServer2$SelectChannelConnectorWithSafeStartup@0.0.0.0:8088
2019-02-18 11:55:35,169 INFO org.apache.hadoop.yarn.webapp.WebApps: Web app cluster started at 8088
2019-02-18 11:55:35,393 INFO org.apache.hadoop.ipc.CallQueueManager: Using callQueue: class java.util.concurrent.LinkedBlockingQueue queueCapacity: 100 scheduler: class org.apache.hadoop.ipc.DefaultRpcScheduler
2019-02-18 11:55:35,407 INFO org.apache.hadoop.ipc.Server: Starting Socket Reader #1 for port 8033
2019-02-18 11:55:35,411 INFO org.apache.hadoop.yarn.factories.impl.pb.RpcServerFactoryPBImpl: Adding protocol org.apache.hadoop.yarn.server.api.ResourceManagerAdministrationProtocolPB to the server
2019-02-18 11:55:35,432 INFO org.apache.hadoop.ipc.Server: IPC Server Responder: starting
2019-02-18 11:55:35,447 INFO org.apache.hadoop.ipc.Server: IPC Server listener on 8033: starting
2019-02-18 11:55:36,897 INFO org.apache.hadoop.yarn.server.resourcemanager.ResourceTrackerService: NodeManager from node ubuntu(cmPort: 33777 httpPort: 8042) registered with capability: <memory:8192, vCores:8>, assigned nodeId ubuntu:33777
2019-02-18 11:55:36,927 INFO org.apache.hadoop.yarn.server.resourcemanager.rmnode.RMNodeImpl: ubuntu:33777 Node Transitioned from NEW to RUNNING
2019-02-18 11:55:36,971 INFO org.apache.hadoop.yarn.server.resourcemanager.scheduler.capacity.CapacityScheduler: Added node ubuntu:33777 clusterResource: <memory:8192, vCores:8>
2019-02-18 12:05:21,024 INFO org.apache.hadoop.yarn.server.resourcemanager.scheduler.AbstractYarnScheduler: Release request cache is cleaned up
2019-02-18 15:09:23,956 ERROR org.apache.hadoop.yarn.server.resourcemanager.ResourceManager: RECEIVED SIGNAL 15: SIGTERM
2019-02-18 15:09:25,109 ERROR org.apache.hadoop.security.token.delegation.AbstractDelegationTokenSecretManager: ExpiredTokenRemover received java.lang.InterruptedException: sleep interrupted
2019-02-18 15:09:25,101 INFO org.apache.hadoop.yarn.server.resourcemanager.ResourceTrackerService: Node with node id : ubuntu:33777 has shutdown, hence unregistering the node.
2019-02-18 15:09:25,186 INFO org.mortbay.log: Stopped HttpServer2$SelectChannelConnectorWithSafeStartup@0.0.0.0:8088
2019-02-18 15:09:25,215 INFO org.apache.hadoop.yarn.server.resourcemanager.rmnode.RMNodeImpl: Deactivating Node ubuntu:33777 as it is now SHUTDOWN
2019-02-18 15:09:25,216 INFO org.apache.hadoop.yarn.server.resourcemanager.rmnode.RMNodeImpl: ubuntu:33777 Node Transitioned from RUNNING to SHUTDOWN
2019-02-18 15:09:25,276 INFO org.apache.hadoop.yarn.server.resourcemanager.scheduler.capacity.CapacityScheduler: Removed node ubuntu:33777 clusterResource: <memory:0, vCores:0>
2019-02-18 15:09:25,361 INFO org.apache.hadoop.ipc.Server: Stopping server on 8032
2019-02-18 15:09:25,503 INFO org.apache.hadoop.ipc.Server: Stopping IPC Server listener on 8032
2019-02-18 15:09:25,517 INFO org.apache.hadoop.ipc.Server: Stopping IPC Server Responder
2019-02-18 15:09:25,531 INFO org.apache.hadoop.ipc.Server: Stopping server on 8033
2019-02-18 15:09:25,534 INFO org.apache.hadoop.ipc.Server: Stopping IPC Server listener on 8033
2019-02-18 15:09:25,544 INFO org.apache.hadoop.ipc.Server: Stopping IPC Server Responder
2019-02-18 15:09:25,550 INFO org.apache.hadoop.yarn.server.resourcemanager.ResourceManager: Transitioning to standby state
2019-02-18 15:09:25,552 WARN org.apache.hadoop.yarn.server.resourcemanager.amlauncher.ApplicationMasterLauncher: org.apache.hadoop.yarn.server.resourcemanager.amlauncher.ApplicationMasterLauncher$LauncherThread interrupted. Returning.
2019-02-18 15:09:25,560 INFO org.apache.hadoop.ipc.Server: Stopping server on 8030
2019-02-18 15:09:25,658 INFO org.apache.hadoop.ipc.Server: Stopping IPC Server listener on 8030
2019-02-18 15:09:25,662 INFO org.apache.hadoop.ipc.Server: Stopping server on 8031
2019-02-18 15:09:25,664 INFO org.apache.hadoop.ipc.Server: Stopping IPC Server Responder
2019-02-18 15:09:25,709 INFO org.apache.hadoop.ipc.Server: Stopping IPC Server listener on 8031
2019-02-18 15:09:25,716 INFO org.apache.hadoop.ipc.Server: Stopping IPC Server Responder
2019-02-18 15:09:25,718 INFO org.apache.hadoop.yarn.util.AbstractLivelinessMonitor: NMLivelinessMonitor thread interrupted
2019-02-18 15:09:25,719 ERROR org.apache.hadoop.yarn.server.resourcemanager.ResourceManager: Returning, interrupted : java.lang.InterruptedException
2019-02-18 15:09:25,738 INFO org.apache.hadoop.yarn.event.AsyncDispatcher: AsyncDispatcher is draining to stop, igonring any new events.
2019-02-18 15:09:25,754 INFO org.apache.hadoop.yarn.util.AbstractLivelinessMonitor: AMLivelinessMonitor thread interrupted
2019-02-18 15:09:25,755 INFO org.apache.hadoop.yarn.util.AbstractLivelinessMonitor: AMLivelinessMonitor thread interrupted
2019-02-18 15:09:25,763 INFO org.apache.hadoop.yarn.util.AbstractLivelinessMonitor: org.apache.hadoop.yarn.server.resourcemanager.rmcontainer.ContainerAllocationExpirer thread interrupted
2019-02-18 15:09:25,765 ERROR org.apache.hadoop.security.token.delegation.AbstractDelegationTokenSecretManager: ExpiredTokenRemover received java.lang.InterruptedException: sleep interrupted
2019-02-18 15:09:25,776 INFO org.apache.hadoop.metrics2.impl.MetricsSystemImpl: Stopping ResourceManager metrics system...
2019-02-18 15:09:25,819 INFO org.apache.hadoop.metrics2.impl.MetricsSystemImpl: ResourceManager metrics system stopped.
2019-02-18 15:09:25,842 INFO org.apache.hadoop.metrics2.impl.MetricsSystemImpl: ResourceManager metrics system shutdown complete.
2019-02-18 15:09:25,844 INFO org.apache.hadoop.yarn.event.AsyncDispatcher: AsyncDispatcher is draining to stop, igonring any new events.
2019-02-18 15:09:25,845 INFO org.apache.hadoop.yarn.server.resourcemanager.ResourceManager: Transitioned to standby state
2019-02-18 15:09:25,846 INFO org.apache.hadoop.yarn.server.resourcemanager.ResourceManager: SHUTDOWN_MSG: 
/************************************************************
SHUTDOWN_MSG: Shutting down ResourceManager at ubuntu/127.0.1.1
************************************************************/
2019-02-20 14:16:15,956 INFO org.apache.hadoop.yarn.server.resourcemanager.ResourceManager: STARTUP_MSG: 
/************************************************************
STARTUP_MSG: Starting ResourceManager
STARTUP_MSG:   user = hdpuser
STARTUP_MSG:   host = ubuntu/127.0.1.1
STARTUP_MSG:   args = []
STARTUP_MSG:   version = 2.8.1
STARTUP_MSG:   build = https://git-wip-us.apache.org/repos/asf/hadoop.git -r 20fe5304904fc2f5a18053c389e43cd26f7a70fe; compiled by 'vinodkv' on 2017-06-02T06:14Z
STARTUP_MSG:   java = 1.8.0_201
************************************************************/
2019-02-20 14:16:15,979 INFO org.apache.hadoop.yarn.server.resourcemanager.ResourceManager: registered UNIX signal handlers for [TERM, HUP, INT]
2019-02-20 14:16:17,729 INFO org.apache.hadoop.conf.Configuration: found resource core-site.xml at file:/usr/local/hadoop-2.8.1/etc/hadoop/core-site.xml
2019-02-20 14:16:18,358 INFO org.apache.hadoop.security.Groups: clearing userToGroupsMap cache
2019-02-20 14:16:18,823 INFO org.apache.hadoop.conf.Configuration: found resource yarn-site.xml at file:/usr/local/hadoop-2.8.1/etc/hadoop/yarn-site.xml
2019-02-20 14:16:20,277 INFO org.apache.hadoop.yarn.event.AsyncDispatcher: Registering class org.apache.hadoop.yarn.server.resourcemanager.RMFatalEventType for class org.apache.hadoop.yarn.server.resourcemanager.ResourceManager$RMFatalEventDispatcher
2019-02-20 14:16:21,982 INFO org.apache.hadoop.yarn.server.resourcemanager.security.NMTokenSecretManagerInRM: NMTokenKeyRollingInterval: 86400000ms and NMTokenKeyActivationDelay: 900000ms
2019-02-20 14:16:22,022 INFO org.apache.hadoop.yarn.server.resourcemanager.security.RMContainerTokenSecretManager: ContainerTokenKeyRollingInterval: 86400000ms and ContainerTokenKeyActivationDelay: 900000ms
2019-02-20 14:16:22,070 INFO org.apache.hadoop.yarn.server.resourcemanager.security.AMRMTokenSecretManager: AMRMTokenKeyRollingInterval: 86400000ms and AMRMTokenKeyActivationDelay: 900000 ms
2019-02-20 14:16:22,371 INFO org.apache.hadoop.yarn.event.AsyncDispatcher: Registering class org.apache.hadoop.yarn.server.resourcemanager.recovery.RMStateStoreEventType for class org.apache.hadoop.yarn.server.resourcemanager.recovery.RMStateStore$ForwardingEventHandler
2019-02-20 14:16:22,383 INFO org.apache.hadoop.yarn.event.AsyncDispatcher: Registering class org.apache.hadoop.yarn.server.resourcemanager.NodesListManagerEventType for class org.apache.hadoop.yarn.server.resourcemanager.NodesListManager
2019-02-20 14:16:22,384 INFO org.apache.hadoop.yarn.server.resourcemanager.ResourceManager: Using Scheduler: org.apache.hadoop.yarn.server.resourcemanager.scheduler.capacity.CapacityScheduler
2019-02-20 14:16:22,535 INFO org.apache.hadoop.yarn.event.AsyncDispatcher: Registering class org.apache.hadoop.yarn.server.resourcemanager.scheduler.event.SchedulerEventType for class org.apache.hadoop.yarn.server.resourcemanager.ResourceManager$SchedulerEventDispatcher
2019-02-20 14:16:22,548 INFO org.apache.hadoop.yarn.event.AsyncDispatcher: Registering class org.apache.hadoop.yarn.server.resourcemanager.rmapp.RMAppEventType for class org.apache.hadoop.yarn.server.resourcemanager.ResourceManager$ApplicationEventDispatcher
2019-02-20 14:16:22,569 INFO org.apache.hadoop.yarn.event.AsyncDispatcher: Registering class org.apache.hadoop.yarn.server.resourcemanager.rmapp.attempt.RMAppAttemptEventType for class org.apache.hadoop.yarn.server.resourcemanager.ResourceManager$ApplicationAttemptEventDispatcher
2019-02-20 14:16:22,571 INFO org.apache.hadoop.yarn.event.AsyncDispatcher: Registering class org.apache.hadoop.yarn.server.resourcemanager.rmnode.RMNodeEventType for class org.apache.hadoop.yarn.server.resourcemanager.ResourceManager$NodeEventDispatcher
2019-02-20 14:16:22,823 INFO org.apache.hadoop.metrics2.impl.MetricsConfig: loaded properties from hadoop-metrics2.properties
2019-02-20 14:16:23,266 INFO org.apache.hadoop.metrics2.impl.MetricsSystemImpl: Scheduled Metric snapshot period at 10 second(s).
2019-02-20 14:16:23,266 INFO org.apache.hadoop.metrics2.impl.MetricsSystemImpl: ResourceManager metrics system started
2019-02-20 14:16:23,360 INFO org.apache.hadoop.yarn.event.AsyncDispatcher: Registering class org.apache.hadoop.yarn.server.resourcemanager.RMAppManagerEventType for class org.apache.hadoop.yarn.server.resourcemanager.RMAppManager
2019-02-20 14:16:23,421 INFO org.apache.hadoop.yarn.event.AsyncDispatcher: Registering class org.apache.hadoop.yarn.server.resourcemanager.amlauncher.AMLauncherEventType for class org.apache.hadoop.yarn.server.resourcemanager.amlauncher.ApplicationMasterLauncher
2019-02-20 14:16:23,429 INFO org.apache.hadoop.yarn.server.resourcemanager.RMNMInfo: Registered RMNMInfo MBean
2019-02-20 14:16:23,498 INFO org.apache.hadoop.yarn.security.YarnAuthorizationProvider: org.apache.hadoop.yarn.security.ConfiguredYarnAuthorizer is instiantiated.
2019-02-20 14:16:23,500 INFO org.apache.hadoop.util.HostsFileReader: Refreshing hosts (include/exclude) list
2019-02-20 14:16:23,554 INFO org.apache.hadoop.conf.Configuration: found resource capacity-scheduler.xml at file:/usr/local/hadoop-2.8.1/etc/hadoop/capacity-scheduler.xml
2019-02-20 14:16:23,949 INFO org.apache.hadoop.yarn.server.resourcemanager.scheduler.capacity.CapacitySchedulerConfiguration: max alloc mb per queue for root is undefined
2019-02-20 14:16:23,949 INFO org.apache.hadoop.yarn.server.resourcemanager.scheduler.capacity.CapacitySchedulerConfiguration: max alloc vcore per queue for root is undefined
2019-02-20 14:16:24,027 INFO org.apache.hadoop.yarn.server.resourcemanager.scheduler.capacity.ParentQueue: root, capacity=1.0, asboluteCapacity=1.0, maxCapacity=1.0, asboluteMaxCapacity=1.0, state=RUNNING, acls=ADMINISTER_QUEUE:*SUBMIT_APP:*, labels=*,, offswitchPerHeartbeatLimit = 1, reservationsContinueLooking=true
2019-02-20 14:16:24,028 INFO org.apache.hadoop.yarn.server.resourcemanager.scheduler.capacity.ParentQueue: Initialized parent-queue root name=root, fullname=root
2019-02-20 14:16:24,068 INFO org.apache.hadoop.yarn.server.resourcemanager.scheduler.capacity.CapacitySchedulerConfiguration: max alloc mb per queue for root.default is undefined
2019-02-20 14:16:24,068 INFO org.apache.hadoop.yarn.server.resourcemanager.scheduler.capacity.CapacitySchedulerConfiguration: max alloc vcore per queue for root.default is undefined
2019-02-20 14:16:24,083 INFO org.apache.hadoop.yarn.server.resourcemanager.scheduler.capacity.LeafQueue: Initializing default
capacity = 1.0 [= (float) configuredCapacity / 100 ]
asboluteCapacity = 1.0 [= parentAbsoluteCapacity * capacity ]
maxCapacity = 1.0 [= configuredMaxCapacity ]
absoluteMaxCapacity = 1.0 [= 1.0 maximumCapacity undefined, (parentAbsoluteMaxCapacity * maximumCapacity) / 100 otherwise ]
userLimit = 100 [= configuredUserLimit ]
userLimitFactor = 1.0 [= configuredUserLimitFactor ]
maxApplications = 10000 [= configuredMaximumSystemApplicationsPerQueue or (int)(configuredMaximumSystemApplications * absoluteCapacity)]
maxApplicationsPerUser = 10000 [= (int)(maxApplications * (userLimit / 100.0f) * userLimitFactor) ]
usedCapacity = 0.0 [= usedResourcesMemory / (clusterResourceMemory * absoluteCapacity)]
absoluteUsedCapacity = 0.0 [= usedResourcesMemory / clusterResourceMemory]
maxAMResourcePerQueuePercent = 0.1 [= configuredMaximumAMResourcePercent ]
minimumAllocationFactor = 0.875 [= (float)(maximumAllocationMemory - minimumAllocationMemory) / maximumAllocationMemory ]
maximumAllocation = <memory:8192, vCores:4> [= configuredMaxAllocation ]
numContainers = 0 [= currentNumContainers ]
state = RUNNING [= configuredState ]
acls = ADMINISTER_QUEUE:*SUBMIT_APP:* [= configuredAcls ]
nodeLocalityDelay = 40
labels=*,
reservationsContinueLooking = true
preemptionDisabled = true
defaultAppPriorityPerQueue = 0
2019-02-20 14:16:24,083 INFO org.apache.hadoop.yarn.server.resourcemanager.scheduler.capacity.CapacityScheduler: Initialized queue: default: capacity=1.0, absoluteCapacity=1.0, usedResources=<memory:0, vCores:0>, usedCapacity=0.0, absoluteUsedCapacity=0.0, numApps=0, numContainers=0
2019-02-20 14:16:24,083 INFO org.apache.hadoop.yarn.server.resourcemanager.scheduler.capacity.CapacityScheduler: Initialized queue: root: numChildQueue= 1, capacity=1.0, absoluteCapacity=1.0, usedResources=<memory:0, vCores:0>usedCapacity=0.0, numApps=0, numContainers=0
2019-02-20 14:16:24,084 INFO org.apache.hadoop.yarn.server.resourcemanager.scheduler.capacity.CapacityScheduler: Initialized root queue root: numChildQueue= 1, capacity=1.0, absoluteCapacity=1.0, usedResources=<memory:0, vCores:0>usedCapacity=0.0, numApps=0, numContainers=0
2019-02-20 14:16:24,084 INFO org.apache.hadoop.yarn.server.resourcemanager.scheduler.capacity.CapacityScheduler: Initialized queue mappings, override: false
2019-02-20 14:16:24,093 INFO org.apache.hadoop.yarn.server.resourcemanager.scheduler.capacity.CapacityScheduler: Initialized CapacityScheduler with calculator=class org.apache.hadoop.yarn.util.resource.DefaultResourceCalculator, minimumAllocation=<<memory:1024, vCores:1>>, maximumAllocation=<<memory:8192, vCores:4>>, asynchronousScheduling=false, asyncScheduleInterval=5ms
2019-02-20 14:16:24,108 INFO org.apache.hadoop.conf.Configuration: dynamic-resources.xml not found
2019-02-20 14:16:24,190 INFO org.apache.hadoop.yarn.server.resourcemanager.metrics.SystemMetricsPublisher: YARN system metrics publishing service is not enabled
2019-02-20 14:16:24,190 INFO org.apache.hadoop.yarn.server.resourcemanager.ResourceManager: Transitioning to active state
2019-02-20 14:16:24,282 INFO org.apache.hadoop.util.JvmPauseMonitor: Starting JVM pause monitor
2019-02-20 14:16:24,376 INFO org.apache.hadoop.yarn.server.resourcemanager.recovery.RMStateStore: Updating AMRMToken
2019-02-20 14:16:24,381 INFO org.apache.hadoop.yarn.server.resourcemanager.security.RMContainerTokenSecretManager: Rolling master-key for container-tokens
2019-02-20 14:16:24,382 INFO org.apache.hadoop.yarn.server.resourcemanager.security.NMTokenSecretManagerInRM: Rolling master-key for nm-tokens
2019-02-20 14:16:24,382 INFO org.apache.hadoop.security.token.delegation.AbstractDelegationTokenSecretManager: Updating the current master key for generating delegation tokens
2019-02-20 14:16:24,384 INFO org.apache.hadoop.yarn.server.resourcemanager.security.RMDelegationTokenSecretManager: storing master key with keyID 1
2019-02-20 14:16:24,384 INFO org.apache.hadoop.yarn.server.resourcemanager.recovery.RMStateStore: Storing RMDTMasterKey.
2019-02-20 14:16:24,410 INFO org.apache.hadoop.yarn.event.AsyncDispatcher: Registering class org.apache.hadoop.yarn.nodelabels.event.NodeLabelsStoreEventType for class org.apache.hadoop.yarn.nodelabels.CommonNodeLabelsManager$ForwardingEventHandler
2019-02-20 14:16:24,396 INFO org.apache.hadoop.security.token.delegation.AbstractDelegationTokenSecretManager: Starting expired delegation token remover thread, tokenRemoverScanInterval=60 min(s)
2019-02-20 14:16:24,420 INFO org.apache.hadoop.security.token.delegation.AbstractDelegationTokenSecretManager: Updating the current master key for generating delegation tokens
2019-02-20 14:16:24,433 INFO org.apache.hadoop.yarn.server.resourcemanager.security.RMDelegationTokenSecretManager: storing master key with keyID 2
2019-02-20 14:16:24,434 INFO org.apache.hadoop.yarn.server.resourcemanager.recovery.RMStateStore: Storing RMDTMasterKey.
2019-02-20 14:16:24,565 INFO org.apache.hadoop.ipc.CallQueueManager: Using callQueue: class java.util.concurrent.LinkedBlockingQueue queueCapacity: 5000 scheduler: class org.apache.hadoop.ipc.DefaultRpcScheduler
2019-02-20 14:16:24,703 INFO org.apache.hadoop.ipc.Server: Starting Socket Reader #1 for port 8031
2019-02-20 14:16:25,479 INFO org.apache.hadoop.yarn.factories.impl.pb.RpcServerFactoryPBImpl: Adding protocol org.apache.hadoop.yarn.server.api.ResourceTrackerPB to the server
2019-02-20 14:16:25,496 INFO org.apache.hadoop.ipc.Server: IPC Server Responder: starting
2019-02-20 14:16:25,492 INFO org.apache.hadoop.ipc.Server: IPC Server listener on 8031: starting
2019-02-20 14:16:25,779 INFO org.apache.hadoop.ipc.CallQueueManager: Using callQueue: class java.util.concurrent.LinkedBlockingQueue queueCapacity: 5000 scheduler: class org.apache.hadoop.ipc.DefaultRpcScheduler
2019-02-20 14:16:25,839 INFO org.apache.hadoop.ipc.Server: Starting Socket Reader #1 for port 8030
2019-02-20 14:16:25,920 INFO org.apache.hadoop.yarn.factories.impl.pb.RpcServerFactoryPBImpl: Adding protocol org.apache.hadoop.yarn.api.ApplicationMasterProtocolPB to the server
2019-02-20 14:16:25,921 INFO org.apache.hadoop.ipc.Server: IPC Server Responder: starting
2019-02-20 14:16:25,923 INFO org.apache.hadoop.ipc.Server: IPC Server listener on 8030: starting
2019-02-20 14:16:26,784 INFO org.apache.hadoop.ipc.CallQueueManager: Using callQueue: class java.util.concurrent.LinkedBlockingQueue queueCapacity: 5000 scheduler: class org.apache.hadoop.ipc.DefaultRpcScheduler
2019-02-20 14:16:26,802 INFO org.apache.hadoop.ipc.Server: Starting Socket Reader #1 for port 8032
2019-02-20 14:16:26,844 INFO org.apache.hadoop.yarn.factories.impl.pb.RpcServerFactoryPBImpl: Adding protocol org.apache.hadoop.yarn.api.ApplicationClientProtocolPB to the server
2019-02-20 14:16:26,859 INFO org.apache.hadoop.ipc.Server: IPC Server Responder: starting
2019-02-20 14:16:26,875 INFO org.apache.hadoop.ipc.Server: IPC Server listener on 8032: starting
2019-02-20 14:16:27,119 INFO org.apache.hadoop.yarn.server.resourcemanager.ResourceManager: Transitioned to active state
2019-02-20 14:16:27,640 INFO org.mortbay.log: Logging to org.slf4j.impl.Log4jLoggerAdapter(org.mortbay.log) via org.mortbay.log.Slf4jLog
2019-02-20 14:16:27,679 INFO org.apache.hadoop.security.authentication.server.AuthenticationFilter: Unable to initialize FileSignerSecretProvider, falling back to use random secrets.
2019-02-20 14:16:27,722 INFO org.apache.hadoop.http.HttpRequestLog: Http request log for http.requests.resourcemanager is not defined
2019-02-20 14:16:27,774 INFO org.apache.hadoop.http.HttpServer2: Added global filter 'safety' (class=org.apache.hadoop.http.HttpServer2$QuotingInputFilter)
2019-02-20 14:16:27,780 INFO org.apache.hadoop.http.HttpServer2: Added filter RMAuthenticationFilter (class=org.apache.hadoop.yarn.server.security.http.RMAuthenticationFilter) to context cluster
2019-02-20 14:16:27,780 INFO org.apache.hadoop.http.HttpServer2: Added filter RMAuthenticationFilter (class=org.apache.hadoop.yarn.server.security.http.RMAuthenticationFilter) to context static
2019-02-20 14:16:27,794 INFO org.apache.hadoop.http.HttpServer2: Added filter RMAuthenticationFilter (class=org.apache.hadoop.yarn.server.security.http.RMAuthenticationFilter) to context logs
2019-02-20 14:16:27,795 INFO org.apache.hadoop.http.HttpServer2: Added filter static_user_filter (class=org.apache.hadoop.http.lib.StaticUserWebFilter$StaticUserFilter) to context cluster
2019-02-20 14:16:27,795 INFO org.apache.hadoop.http.HttpServer2: Added filter static_user_filter (class=org.apache.hadoop.http.lib.StaticUserWebFilter$StaticUserFilter) to context static
2019-02-20 14:16:27,798 INFO org.apache.hadoop.http.HttpServer2: Added filter static_user_filter (class=org.apache.hadoop.http.lib.StaticUserWebFilter$StaticUserFilter) to context logs
2019-02-20 14:16:27,814 INFO org.apache.hadoop.http.HttpServer2: adding path spec: /cluster/*
2019-02-20 14:16:27,814 INFO org.apache.hadoop.http.HttpServer2: adding path spec: /ws/*
2019-02-20 14:16:30,278 INFO org.apache.hadoop.yarn.webapp.WebApps: Registered webapp guice modules
2019-02-20 14:16:30,289 INFO org.apache.hadoop.http.HttpServer2: Jetty bound to port 8088
2019-02-20 14:16:30,289 INFO org.mortbay.log: jetty-6.1.26
2019-02-20 14:16:30,405 INFO org.mortbay.log: Extract jar:file:/usr/local/hadoop-2.8.1/share/hadoop/yarn/hadoop-yarn-common-2.8.1.jar!/webapps/cluster to /tmp/Jetty_0_0_0_0_8088_cluster____u0rgz3/webapp
2019-02-20 14:16:31,631 INFO org.apache.hadoop.security.token.delegation.AbstractDelegationTokenSecretManager: Updating the current master key for generating delegation tokens
2019-02-20 14:16:31,643 INFO org.apache.hadoop.security.token.delegation.AbstractDelegationTokenSecretManager: Starting expired delegation token remover thread, tokenRemoverScanInterval=60 min(s)
2019-02-20 14:16:31,644 INFO org.apache.hadoop.security.token.delegation.AbstractDelegationTokenSecretManager: Updating the current master key for generating delegation tokens
2019-02-20 14:16:37,917 INFO org.mortbay.log: Started HttpServer2$SelectChannelConnectorWithSafeStartup@0.0.0.0:8088
2019-02-20 14:16:37,917 INFO org.apache.hadoop.yarn.webapp.WebApps: Web app cluster started at 8088
2019-02-20 14:16:38,130 INFO org.apache.hadoop.ipc.CallQueueManager: Using callQueue: class java.util.concurrent.LinkedBlockingQueue queueCapacity: 100 scheduler: class org.apache.hadoop.ipc.DefaultRpcScheduler
2019-02-20 14:16:38,142 INFO org.apache.hadoop.ipc.Server: Starting Socket Reader #1 for port 8033
2019-02-20 14:16:38,182 INFO org.apache.hadoop.yarn.factories.impl.pb.RpcServerFactoryPBImpl: Adding protocol org.apache.hadoop.yarn.server.api.ResourceManagerAdministrationProtocolPB to the server
2019-02-20 14:16:38,186 INFO org.apache.hadoop.ipc.Server: IPC Server Responder: starting
2019-02-20 14:16:38,190 INFO org.apache.hadoop.ipc.Server: IPC Server listener on 8033: starting
2019-02-20 14:16:40,198 INFO org.apache.hadoop.yarn.server.resourcemanager.ResourceTrackerService: NodeManager from node ubuntu(cmPort: 39087 httpPort: 8042) registered with capability: <memory:8192, vCores:8>, assigned nodeId ubuntu:39087
2019-02-20 14:16:40,228 INFO org.apache.hadoop.yarn.server.resourcemanager.rmnode.RMNodeImpl: ubuntu:39087 Node Transitioned from NEW to RUNNING
2019-02-20 14:16:40,265 INFO org.apache.hadoop.yarn.server.resourcemanager.scheduler.capacity.CapacityScheduler: Added node ubuntu:39087 clusterResource: <memory:8192, vCores:8>
2019-02-20 14:26:23,555 INFO org.apache.hadoop.yarn.server.resourcemanager.scheduler.AbstractYarnScheduler: Release request cache is cleaned up
2019-02-20 14:27:09,632 INFO org.apache.hadoop.yarn.server.resourcemanager.ClientRMService: Allocated new applicationId: 1
2019-02-20 14:27:12,168 INFO org.apache.hadoop.yarn.server.resourcemanager.scheduler.capacity.CapacityScheduler: Application 'application_1550700984206_0001' is submitted without priority hence considering default queue/cluster priority: 0
2019-02-20 14:27:12,168 INFO org.apache.hadoop.yarn.server.resourcemanager.scheduler.capacity.CapacityScheduler: Priority '0' is acceptable in queue : default for application: application_1550700984206_0001 for the user: hdpuser
2019-02-20 14:27:12,204 INFO org.apache.hadoop.yarn.server.resourcemanager.rmapp.RMAppImpl: Storing application with id application_1550700984206_0001
2019-02-20 14:27:12,205 INFO org.apache.hadoop.yarn.server.resourcemanager.ClientRMService: Application with id 1 submitted by user hdpuser
2019-02-20 14:27:12,218 INFO org.apache.hadoop.yarn.server.resourcemanager.RMAuditLogger: USER=hdpuser	IP=127.0.0.1	OPERATION=Submit Application Request	TARGET=ClientRMService	RESULT=SUCCESS	APPID=application_1550700984206_0001
2019-02-20 14:27:12,251 INFO org.apache.hadoop.yarn.server.resourcemanager.recovery.RMStateStore: Storing info for app: application_1550700984206_0001
2019-02-20 14:27:12,251 INFO org.apache.hadoop.yarn.server.resourcemanager.rmapp.RMAppImpl: application_1550700984206_0001 State change from NEW to NEW_SAVING on event=START
2019-02-20 14:27:12,255 INFO org.apache.hadoop.yarn.server.resourcemanager.rmapp.RMAppImpl: application_1550700984206_0001 State change from NEW_SAVING to SUBMITTED on event=APP_NEW_SAVED
2019-02-20 14:27:12,261 INFO org.apache.hadoop.yarn.server.resourcemanager.scheduler.capacity.ParentQueue: Application added - appId: application_1550700984206_0001 user: hdpuser leaf-queue of parent: root #applications: 1
2019-02-20 14:27:12,262 INFO org.apache.hadoop.yarn.server.resourcemanager.scheduler.capacity.CapacityScheduler: Accepted application application_1550700984206_0001 from user: hdpuser, in queue: default
2019-02-20 14:27:12,374 INFO org.apache.hadoop.yarn.server.resourcemanager.rmapp.RMAppImpl: application_1550700984206_0001 State change from SUBMITTED to ACCEPTED on event=APP_ACCEPTED
2019-02-20 14:27:12,452 INFO org.apache.hadoop.yarn.server.resourcemanager.ApplicationMasterService: Registering app attempt : appattempt_1550700984206_0001_000001
2019-02-20 14:27:12,455 INFO org.apache.hadoop.yarn.server.resourcemanager.rmapp.attempt.RMAppAttemptImpl: appattempt_1550700984206_0001_000001 State change from NEW to SUBMITTED
2019-02-20 14:27:12,489 WARN org.apache.hadoop.yarn.server.resourcemanager.scheduler.capacity.LeafQueue: maximum-am-resource-percent is insufficient to start a single application in queue, it is likely set too low. skipping enforcement to allow at least one application to start
2019-02-20 14:27:12,490 WARN org.apache.hadoop.yarn.server.resourcemanager.scheduler.capacity.LeafQueue: maximum-am-resource-percent is insufficient to start a single application in queue for user, it is likely set too low. skipping enforcement to allow at least one application to start
2019-02-20 14:27:12,493 INFO org.apache.hadoop.yarn.server.resourcemanager.scheduler.capacity.LeafQueue: Application application_1550700984206_0001 from user: hdpuser activated in queue: default
2019-02-20 14:27:12,494 INFO org.apache.hadoop.yarn.server.resourcemanager.scheduler.capacity.LeafQueue: Application added - appId: application_1550700984206_0001 user: hdpuser, leaf-queue: default #user-pending-applications: 0 #user-active-applications: 1 #queue-pending-applications: 0 #queue-active-applications: 1
2019-02-20 14:27:12,494 INFO org.apache.hadoop.yarn.server.resourcemanager.scheduler.capacity.CapacityScheduler: Added Application Attempt appattempt_1550700984206_0001_000001 to scheduler from user hdpuser in queue default
2019-02-20 14:27:12,503 INFO org.apache.hadoop.yarn.server.resourcemanager.rmapp.attempt.RMAppAttemptImpl: appattempt_1550700984206_0001_000001 State change from SUBMITTED to SCHEDULED
2019-02-20 14:27:12,536 INFO org.apache.hadoop.yarn.server.resourcemanager.rmcontainer.RMContainerImpl: container_1550700984206_0001_01_000001 Container Transitioned from NEW to ALLOCATED
2019-02-20 14:27:12,536 INFO org.apache.hadoop.yarn.server.resourcemanager.RMAuditLogger: USER=hdpuser	OPERATION=AM Allocated Container	TARGET=SchedulerApp	RESULT=SUCCESS	APPID=application_1550700984206_0001	CONTAINERID=container_1550700984206_0001_01_000001
2019-02-20 14:27:12,542 INFO org.apache.hadoop.yarn.server.resourcemanager.scheduler.SchedulerNode: Assigned container container_1550700984206_0001_01_000001 of capacity <memory:2048, vCores:1> on host ubuntu:39087, which has 1 containers, <memory:2048, vCores:1> used and <memory:6144, vCores:7> available after allocation
2019-02-20 14:27:12,542 INFO org.apache.hadoop.yarn.server.resourcemanager.scheduler.capacity.allocator.AbstractContainerAllocator: assignedContainer application attempt=appattempt_1550700984206_0001_000001 container=container_1550700984206_0001_01_000001 queue=org.apache.hadoop.yarn.server.resourcemanager.scheduler.capacity.allocator.RegularContainerAllocator@17cd735b clusterResource=<memory:8192, vCores:8> type=OFF_SWITCH
2019-02-20 14:27:12,602 INFO org.apache.hadoop.yarn.server.resourcemanager.security.NMTokenSecretManagerInRM: Sending NMToken for nodeId : ubuntu:39087 for container : container_1550700984206_0001_01_000001
2019-02-20 14:27:12,635 INFO org.apache.hadoop.yarn.server.resourcemanager.rmcontainer.RMContainerImpl: container_1550700984206_0001_01_000001 Container Transitioned from ALLOCATED to ACQUIRED
2019-02-20 14:27:12,636 INFO org.apache.hadoop.yarn.server.resourcemanager.scheduler.capacity.ParentQueue: Re-sorting assigned queue: root.default stats: default: capacity=1.0, absoluteCapacity=1.0, usedResources=<memory:2048, vCores:1>, usedCapacity=0.25, absoluteUsedCapacity=0.25, numApps=1, numContainers=1
2019-02-20 14:27:12,637 INFO org.apache.hadoop.yarn.server.resourcemanager.scheduler.capacity.ParentQueue: assignedContainer queue=root usedCapacity=0.25 absoluteUsedCapacity=0.25 used=<memory:2048, vCores:1> cluster=<memory:8192, vCores:8>
2019-02-20 14:27:12,640 INFO org.apache.hadoop.yarn.server.resourcemanager.security.NMTokenSecretManagerInRM: Clear node set for appattempt_1550700984206_0001_000001
2019-02-20 14:27:12,641 INFO org.apache.hadoop.yarn.server.resourcemanager.rmapp.attempt.RMAppAttemptImpl: Storing attempt: AppId: application_1550700984206_0001 AttemptId: appattempt_1550700984206_0001_000001 MasterContainer: Container: [ContainerId: container_1550700984206_0001_01_000001, Version: 0, NodeId: ubuntu:39087, NodeHttpAddress: ubuntu:8042, Resource: <memory:2048, vCores:1>, Priority: 0, Token: Token { kind: ContainerToken, service: 127.0.1.1:39087 }, ]
2019-02-20 14:27:12,672 INFO org.apache.hadoop.yarn.server.resourcemanager.rmapp.attempt.RMAppAttemptImpl: appattempt_1550700984206_0001_000001 State change from SCHEDULED to ALLOCATED_SAVING
2019-02-20 14:27:12,719 INFO org.apache.hadoop.yarn.server.resourcemanager.rmapp.attempt.RMAppAttemptImpl: appattempt_1550700984206_0001_000001 State change from ALLOCATED_SAVING to ALLOCATED
2019-02-20 14:27:12,739 INFO org.apache.hadoop.yarn.server.resourcemanager.amlauncher.AMLauncher: Launching masterappattempt_1550700984206_0001_000001
2019-02-20 14:27:13,018 INFO org.apache.hadoop.yarn.server.resourcemanager.amlauncher.AMLauncher: Setting up container Container: [ContainerId: container_1550700984206_0001_01_000001, Version: 0, NodeId: ubuntu:39087, NodeHttpAddress: ubuntu:8042, Resource: <memory:2048, vCores:1>, Priority: 0, Token: Token { kind: ContainerToken, service: 127.0.1.1:39087 }, ] for AM appattempt_1550700984206_0001_000001
2019-02-20 14:27:13,019 INFO org.apache.hadoop.yarn.server.resourcemanager.security.AMRMTokenSecretManager: Create AMRMToken for ApplicationAttempt: appattempt_1550700984206_0001_000001
2019-02-20 14:27:13,024 INFO org.apache.hadoop.yarn.server.resourcemanager.security.AMRMTokenSecretManager: Creating password for appattempt_1550700984206_0001_000001
2019-02-20 14:27:13,805 INFO org.apache.hadoop.yarn.server.resourcemanager.amlauncher.AMLauncher: Done launching container Container: [ContainerId: container_1550700984206_0001_01_000001, Version: 0, NodeId: ubuntu:39087, NodeHttpAddress: ubuntu:8042, Resource: <memory:2048, vCores:1>, Priority: 0, Token: Token { kind: ContainerToken, service: 127.0.1.1:39087 }, ] for AM appattempt_1550700984206_0001_000001
2019-02-20 14:27:13,808 INFO org.apache.hadoop.yarn.server.resourcemanager.rmapp.attempt.RMAppAttemptImpl: appattempt_1550700984206_0001_000001 State change from ALLOCATED to LAUNCHED
2019-02-20 14:27:14,467 INFO org.apache.hadoop.yarn.server.resourcemanager.rmcontainer.RMContainerImpl: container_1550700984206_0001_01_000001 Container Transitioned from ACQUIRED to RUNNING
2019-02-20 14:27:30,215 INFO SecurityLogger.org.apache.hadoop.ipc.Server: Auth successful for appattempt_1550700984206_0001_000001 (auth:SIMPLE)
2019-02-20 14:27:30,260 INFO org.apache.hadoop.yarn.server.resourcemanager.ApplicationMasterService: AM registration appattempt_1550700984206_0001_000001
2019-02-20 14:27:30,265 INFO org.apache.hadoop.yarn.server.resourcemanager.rmapp.attempt.RMAppAttemptImpl: appattempt_1550700984206_0001_000001 State change from LAUNCHED to RUNNING
2019-02-20 14:27:30,265 INFO org.apache.hadoop.yarn.server.resourcemanager.rmapp.RMAppImpl: application_1550700984206_0001 State change from ACCEPTED to RUNNING on event=ATTEMPT_REGISTERED
2019-02-20 14:27:30,265 INFO org.apache.hadoop.yarn.server.resourcemanager.RMAuditLogger: USER=hdpuser	IP=127.0.0.1	OPERATION=Register App Master	TARGET=ApplicationMasterService	RESULT=SUCCESS	APPID=application_1550700984206_0001	APPATTEMPTID=appattempt_1550700984206_0001_000001
2019-02-20 14:27:32,550 INFO org.apache.hadoop.yarn.server.resourcemanager.rmcontainer.RMContainerImpl: container_1550700984206_0001_01_000002 Container Transitioned from NEW to ALLOCATED
2019-02-20 14:27:32,551 INFO org.apache.hadoop.yarn.server.resourcemanager.RMAuditLogger: USER=hdpuser	OPERATION=AM Allocated Container	TARGET=SchedulerApp	RESULT=SUCCESS	APPID=application_1550700984206_0001	CONTAINERID=container_1550700984206_0001_01_000002
2019-02-20 14:27:32,551 INFO org.apache.hadoop.yarn.server.resourcemanager.scheduler.SchedulerNode: Assigned container container_1550700984206_0001_01_000002 of capacity <memory:1024, vCores:1> on host ubuntu:39087, which has 2 containers, <memory:3072, vCores:2> used and <memory:5120, vCores:6> available after allocation
2019-02-20 14:27:32,551 INFO org.apache.hadoop.yarn.server.resourcemanager.scheduler.capacity.allocator.AbstractContainerAllocator: assignedContainer application attempt=appattempt_1550700984206_0001_000001 container=container_1550700984206_0001_01_000002 queue=org.apache.hadoop.yarn.server.resourcemanager.scheduler.capacity.allocator.RegularContainerAllocator@17cd735b clusterResource=<memory:8192, vCores:8> type=NODE_LOCAL
2019-02-20 14:27:32,551 INFO org.apache.hadoop.yarn.server.resourcemanager.scheduler.capacity.ParentQueue: Re-sorting assigned queue: root.default stats: default: capacity=1.0, absoluteCapacity=1.0, usedResources=<memory:3072, vCores:2>, usedCapacity=0.375, absoluteUsedCapacity=0.375, numApps=1, numContainers=2
2019-02-20 14:27:32,551 INFO org.apache.hadoop.yarn.server.resourcemanager.scheduler.capacity.ParentQueue: assignedContainer queue=root usedCapacity=0.375 absoluteUsedCapacity=0.375 used=<memory:3072, vCores:2> cluster=<memory:8192, vCores:8>
2019-02-20 14:27:32,660 INFO org.apache.hadoop.yarn.server.resourcemanager.security.NMTokenSecretManagerInRM: Sending NMToken for nodeId : ubuntu:39087 for container : container_1550700984206_0001_01_000002
2019-02-20 14:27:32,666 INFO org.apache.hadoop.yarn.server.resourcemanager.rmcontainer.RMContainerImpl: container_1550700984206_0001_01_000002 Container Transitioned from ALLOCATED to ACQUIRED
2019-02-20 14:27:33,555 INFO org.apache.hadoop.yarn.server.resourcemanager.rmcontainer.RMContainerImpl: container_1550700984206_0001_01_000002 Container Transitioned from ACQUIRED to RUNNING
2019-02-20 14:27:33,740 INFO org.apache.hadoop.yarn.server.resourcemanager.scheduler.AppSchedulingInfo: checking for deactivate of application :application_1550700984206_0001
2019-02-20 14:27:48,822 INFO org.apache.hadoop.yarn.server.resourcemanager.rmcontainer.RMContainerImpl: container_1550700984206_0001_01_000002 Container Transitioned from RUNNING to COMPLETED
2019-02-20 14:27:48,822 INFO org.apache.hadoop.yarn.server.resourcemanager.RMAuditLogger: USER=hdpuser	OPERATION=AM Released Container	TARGET=SchedulerApp	RESULT=SUCCESS	APPID=application_1550700984206_0001	CONTAINERID=container_1550700984206_0001_01_000002
2019-02-20 14:27:48,857 INFO org.apache.hadoop.yarn.server.resourcemanager.scheduler.SchedulerNode: Released container container_1550700984206_0001_01_000002 of capacity <memory:1024, vCores:1> on host ubuntu:39087, which currently has 1 containers, <memory:2048, vCores:1> used and <memory:6144, vCores:7> available, release resources=true
2019-02-20 14:27:50,836 INFO org.apache.hadoop.yarn.server.resourcemanager.rmcontainer.RMContainerImpl: container_1550700984206_0001_01_000003 Container Transitioned from NEW to ALLOCATED
2019-02-20 14:27:50,840 INFO org.apache.hadoop.yarn.server.resourcemanager.RMAuditLogger: USER=hdpuser	OPERATION=AM Allocated Container	TARGET=SchedulerApp	RESULT=SUCCESS	APPID=application_1550700984206_0001	CONTAINERID=container_1550700984206_0001_01_000003
2019-02-20 14:27:50,841 INFO org.apache.hadoop.yarn.server.resourcemanager.scheduler.SchedulerNode: Assigned container container_1550700984206_0001_01_000003 of capacity <memory:1024, vCores:1> on host ubuntu:39087, which has 2 containers, <memory:3072, vCores:2> used and <memory:5120, vCores:6> available after allocation
2019-02-20 14:27:50,841 INFO org.apache.hadoop.yarn.server.resourcemanager.scheduler.capacity.allocator.AbstractContainerAllocator: assignedContainer application attempt=appattempt_1550700984206_0001_000001 container=container_1550700984206_0001_01_000003 queue=org.apache.hadoop.yarn.server.resourcemanager.scheduler.capacity.allocator.RegularContainerAllocator@17cd735b clusterResource=<memory:8192, vCores:8> type=OFF_SWITCH
2019-02-20 14:27:50,850 INFO org.apache.hadoop.yarn.server.resourcemanager.scheduler.capacity.ParentQueue: Re-sorting assigned queue: root.default stats: default: capacity=1.0, absoluteCapacity=1.0, usedResources=<memory:3072, vCores:2>, usedCapacity=0.375, absoluteUsedCapacity=0.375, numApps=1, numContainers=2
2019-02-20 14:27:50,850 INFO org.apache.hadoop.yarn.server.resourcemanager.scheduler.capacity.ParentQueue: assignedContainer queue=root usedCapacity=0.375 absoluteUsedCapacity=0.375 used=<memory:3072, vCores:2> cluster=<memory:8192, vCores:8>
2019-02-20 14:27:50,911 INFO org.apache.hadoop.yarn.server.resourcemanager.rmcontainer.RMContainerImpl: container_1550700984206_0001_01_000003 Container Transitioned from ALLOCATED to ACQUIRED
2019-02-20 14:27:51,849 INFO org.apache.hadoop.yarn.server.resourcemanager.rmcontainer.RMContainerImpl: container_1550700984206_0001_01_000003 Container Transitioned from ACQUIRED to RUNNING
2019-02-20 14:27:51,934 INFO org.apache.hadoop.yarn.server.resourcemanager.scheduler.AppSchedulingInfo: checking for deactivate of application :application_1550700984206_0001
2019-02-20 14:28:14,930 INFO org.apache.hadoop.yarn.server.resourcemanager.rmcontainer.RMContainerImpl: container_1550700984206_0001_01_000003 Container Transitioned from RUNNING to COMPLETED
2019-02-20 14:28:14,930 INFO org.apache.hadoop.yarn.server.resourcemanager.RMAuditLogger: USER=hdpuser	OPERATION=AM Released Container	TARGET=SchedulerApp	RESULT=SUCCESS	APPID=application_1550700984206_0001	CONTAINERID=container_1550700984206_0001_01_000003
2019-02-20 14:28:14,930 INFO org.apache.hadoop.yarn.server.resourcemanager.scheduler.SchedulerNode: Released container container_1550700984206_0001_01_000003 of capacity <memory:1024, vCores:1> on host ubuntu:39087, which currently has 1 containers, <memory:2048, vCores:1> used and <memory:6144, vCores:7> available, release resources=true
2019-02-20 14:28:16,205 INFO org.apache.hadoop.yarn.server.resourcemanager.rmapp.attempt.RMAppAttemptImpl: Updating application attempt appattempt_1550700984206_0001_000001 with final state: FINISHING, and exit status: -1000
2019-02-20 14:28:16,218 INFO org.apache.hadoop.yarn.server.resourcemanager.rmapp.attempt.RMAppAttemptImpl: appattempt_1550700984206_0001_000001 State change from RUNNING to FINAL_SAVING
2019-02-20 14:28:16,218 INFO org.apache.hadoop.yarn.server.resourcemanager.rmapp.attempt.RMAppAttemptImpl: appattempt_1550700984206_0001_000001 State change from FINAL_SAVING to FINISHING
2019-02-20 14:28:16,218 INFO org.apache.hadoop.yarn.server.resourcemanager.rmapp.RMAppImpl: Updating application application_1550700984206_0001 with final state: FINISHING
2019-02-20 14:28:16,218 INFO org.apache.hadoop.yarn.server.resourcemanager.recovery.RMStateStore: Updating info for app: application_1550700984206_0001
2019-02-20 14:28:16,219 INFO org.apache.hadoop.yarn.server.resourcemanager.rmapp.RMAppImpl: application_1550700984206_0001 State change from RUNNING to FINAL_SAVING on event=ATTEMPT_UNREGISTERED
2019-02-20 14:28:16,219 INFO org.apache.hadoop.yarn.server.resourcemanager.rmapp.RMAppImpl: application_1550700984206_0001 State change from FINAL_SAVING to FINISHING on event=APP_UPDATE_SAVED
2019-02-20 14:28:17,227 INFO org.apache.hadoop.yarn.server.resourcemanager.ApplicationMasterService: application_1550700984206_0001 unregistered successfully. 
2019-02-20 14:28:22,785 INFO org.apache.hadoop.yarn.server.resourcemanager.rmcontainer.RMContainerImpl: container_1550700984206_0001_01_000001 Container Transitioned from RUNNING to COMPLETED
2019-02-20 14:28:22,785 INFO org.apache.hadoop.yarn.server.resourcemanager.RMAuditLogger: USER=hdpuser	OPERATION=AM Released Container	TARGET=SchedulerApp	RESULT=SUCCESS	APPID=application_1550700984206_0001	CONTAINERID=container_1550700984206_0001_01_000001
2019-02-20 14:28:22,785 INFO org.apache.hadoop.yarn.server.resourcemanager.scheduler.SchedulerNode: Released container container_1550700984206_0001_01_000001 of capacity <memory:2048, vCores:1> on host ubuntu:39087, which currently has 0 containers, <memory:0, vCores:0> used and <memory:8192, vCores:8> available, release resources=true
2019-02-20 14:28:22,786 INFO org.apache.hadoop.yarn.server.resourcemanager.ApplicationMasterService: Unregistering app attempt : appattempt_1550700984206_0001_000001
2019-02-20 14:28:22,794 INFO org.apache.hadoop.yarn.server.resourcemanager.security.AMRMTokenSecretManager: Application finished, removing password for appattempt_1550700984206_0001_000001
2019-02-20 14:28:22,803 INFO org.apache.hadoop.yarn.server.resourcemanager.rmapp.attempt.RMAppAttemptImpl: appattempt_1550700984206_0001_000001 State change from FINISHING to FINISHED
2019-02-20 14:28:22,810 INFO org.apache.hadoop.yarn.server.resourcemanager.rmapp.RMAppImpl: application_1550700984206_0001 State change from FINISHING to FINISHED on event=ATTEMPT_FINISHED
2019-02-20 14:28:22,811 INFO org.apache.hadoop.yarn.server.resourcemanager.scheduler.capacity.CapacityScheduler: Application Attempt appattempt_1550700984206_0001_000001 is done. finalState=FINISHED
2019-02-20 14:28:22,812 INFO org.apache.hadoop.yarn.server.resourcemanager.scheduler.AppSchedulingInfo: Application application_1550700984206_0001 requests cleared
2019-02-20 14:28:22,812 INFO org.apache.hadoop.yarn.server.resourcemanager.scheduler.capacity.LeafQueue: Application removed - appId: application_1550700984206_0001 user: hdpuser queue: default #user-pending-applications: 0 #user-active-applications: 0 #queue-pending-applications: 0 #queue-active-applications: 0
2019-02-20 14:28:22,818 INFO org.apache.hadoop.yarn.server.resourcemanager.scheduler.capacity.ParentQueue: Application removed - appId: application_1550700984206_0001 user: hdpuser leaf-queue of parent: root #applications: 0
2019-02-20 14:28:22,821 INFO org.apache.hadoop.yarn.server.resourcemanager.amlauncher.AMLauncher: Cleaning master appattempt_1550700984206_0001_000001
2019-02-20 14:28:22,827 INFO org.apache.hadoop.yarn.server.resourcemanager.RMAuditLogger: USER=hdpuser	OPERATION=Application Finished - Succeeded	TARGET=RMAppManager	RESULT=SUCCESS	APPID=application_1550700984206_0001
2019-02-20 14:28:22,869 INFO org.apache.hadoop.yarn.server.resourcemanager.RMAppManager$ApplicationSummary: appId=application_1550700984206_0001,name=word count,user=hdpuser,queue=default,state=FINISHED,trackingUrl=http://ubuntu:8088/proxy/application_1550700984206_0001/,appMasterHost=ubuntu,startTime=1550701632191,finishTime=1550701696218,finalStatus=SUCCEEDED,memorySeconds=185206,vcoreSeconds=110,preemptedMemorySeconds=0,preemptedVcoreSeconds=0,preemptedAMContainers=0,preemptedNonAMContainers=0,preemptedResources=<memory:0\, vCores:0>,applicationType=MAPREDUCE
